2019-12-20 02:29:16 django.request 93 WARNING Not Found: /
2019-12-20 02:29:23 django.request 93 WARNING Not Found: /favicon.ico
2019-12-20 07:26:58 django.request 118 ERROR Internal Server Error: /dashboard/list/
Traceback (most recent call last):
  File "/home/vagrant/project/env/lib/python3.6/site-packages/django/core/handlers/exception.py", line 35, in inner
    response = get_response(request)
  File "/home/vagrant/project/env/lib/python3.6/site-packages/django/core/handlers/base.py", line 128, in _get_response
    response = self.process_exception_by_middleware(e, request)
  File "/home/vagrant/project/env/lib/python3.6/site-packages/django/core/handlers/base.py", line 126, in _get_response
    response = wrapped_callback(request, *callback_args, **callback_kwargs)
  File "/home/vagrant/project/env/lib/python3.6/site-packages/django/views/generic/base.py", line 69, in view
    return self.dispatch(request, *args, **kwargs)
  File "/home/vagrant/project/env/lib/python3.6/site-packages/django/views/generic/base.py", line 89, in dispatch
    return handler(request, *args, **kwargs)
  File "/home/vagrant/project/env/lib/python3.6/site-packages/django/views/generic/base.py", line 150, in get
    context = self.get_context_data(**kwargs)
  File "/home/vagrant/project/ops/dashboard/views.py", line 77, in get_context_data
    user = User.objects.get(pk=self.request.GET.get('id'))
  File "/home/vagrant/project/env/lib/python3.6/site-packages/django/db/models/manager.py", line 82, in manager_method
    return getattr(self.get_queryset(), name)(*args, **kwargs)
  File "/home/vagrant/project/env/lib/python3.6/site-packages/django/db/models/query.py", line 403, in get
    self.model._meta.object_name
django.contrib.auth.models.DoesNotExist: User matching query does not exist.
2019-12-20 07:27:11 django.request 118 ERROR Internal Server Error: /dashboard/list/
Traceback (most recent call last):
  File "/home/vagrant/project/env/lib/python3.6/site-packages/django/core/handlers/exception.py", line 35, in inner
    response = get_response(request)
  File "/home/vagrant/project/env/lib/python3.6/site-packages/django/core/handlers/base.py", line 128, in _get_response
    response = self.process_exception_by_middleware(e, request)
  File "/home/vagrant/project/env/lib/python3.6/site-packages/django/core/handlers/base.py", line 126, in _get_response
    response = wrapped_callback(request, *callback_args, **callback_kwargs)
  File "/home/vagrant/project/env/lib/python3.6/site-packages/django/views/generic/base.py", line 69, in view
    return self.dispatch(request, *args, **kwargs)
  File "/home/vagrant/project/env/lib/python3.6/site-packages/django/views/generic/base.py", line 89, in dispatch
    return handler(request, *args, **kwargs)
  File "/home/vagrant/project/env/lib/python3.6/site-packages/django/views/generic/base.py", line 150, in get
    context = self.get_context_data(**kwargs)
  File "/home/vagrant/project/ops/dashboard/views.py", line 77, in get_context_data
    user = User.objects.get(pk=self.request.GET.get('id'))
  File "/home/vagrant/project/env/lib/python3.6/site-packages/django/db/models/manager.py", line 82, in manager_method
    return getattr(self.get_queryset(), name)(*args, **kwargs)
  File "/home/vagrant/project/env/lib/python3.6/site-packages/django/db/models/query.py", line 403, in get
    self.model._meta.object_name
django.contrib.auth.models.DoesNotExist: User matching query does not exist.
2019-12-20 07:28:44 django.request 118 ERROR Internal Server Error: /dashboard/list/
Traceback (most recent call last):
  File "/home/vagrant/project/env/lib/python3.6/site-packages/django/core/handlers/exception.py", line 35, in inner
    response = get_response(request)
  File "/home/vagrant/project/env/lib/python3.6/site-packages/django/core/handlers/base.py", line 128, in _get_response
    response = self.process_exception_by_middleware(e, request)
  File "/home/vagrant/project/env/lib/python3.6/site-packages/django/core/handlers/base.py", line 126, in _get_response
    response = wrapped_callback(request, *callback_args, **callback_kwargs)
  File "/home/vagrant/project/env/lib/python3.6/site-packages/django/views/generic/base.py", line 69, in view
    return self.dispatch(request, *args, **kwargs)
  File "/home/vagrant/project/env/lib/python3.6/site-packages/django/views/generic/base.py", line 89, in dispatch
    return handler(request, *args, **kwargs)
  File "/home/vagrant/project/env/lib/python3.6/site-packages/django/views/generic/base.py", line 150, in get
    context = self.get_context_data(**kwargs)
  File "/home/vagrant/project/ops/dashboard/views.py", line 76, in get_context_data
    user = User.objects.get(pk=self.request.GET.get('id'))
  File "/home/vagrant/project/env/lib/python3.6/site-packages/django/db/models/manager.py", line 82, in manager_method
    return getattr(self.get_queryset(), name)(*args, **kwargs)
  File "/home/vagrant/project/env/lib/python3.6/site-packages/django/db/models/query.py", line 403, in get
    self.model._meta.object_name
django.contrib.auth.models.DoesNotExist: User matching query does not exist.
2019-12-23 10:47:02 django.request 93 WARNING Not Found: /
2019-12-23 10:47:03 django.request 93 WARNING Not Found: /favicon.ico
